ERROR 2023-08-16 13:20:29,897 log Internal Server Error: /disburstment/installment/1/
Traceback (most recent call last):
  File "D:\python files\CJC_Final_Project\venv\lib\site-packages\django\core\handlers\exception.py", line 55, in inner
    response = get_response(request)
  File "D:\python files\CJC_Final_Project\venv\lib\site-packages\django\core\handlers\base.py", line 197, in _get_response
    response = wrapped_callback(request, *callback_args, **callback_kwargs)
  File "D:\python files\CJC_Final_Project\venv\lib\site-packages\django\views\decorators\csrf.py", line 56, in wrapper_view
    return view_func(*args, **kwargs)
  File "D:\python files\CJC_Final_Project\venv\lib\site-packages\django\views\generic\base.py", line 104, in view
    return self.dispatch(request, *args, **kwargs)
  File "D:\python files\CJC_Final_Project\venv\lib\site-packages\rest_framework\views.py", line 509, in dispatch
    response = self.handle_exception(exc)
  File "D:\python files\CJC_Final_Project\venv\lib\site-packages\rest_framework\views.py", line 469, in handle_exception
    self.raise_uncaught_exception(exc)
  File "D:\python files\CJC_Final_Project\venv\lib\site-packages\rest_framework\views.py", line 480, in raise_uncaught_exception
    raise exc
  File "D:\python files\CJC_Final_Project\venv\lib\site-packages\rest_framework\views.py", line 506, in dispatch
    response = handler(request, *args, **kwargs)
  File "D:\python files\CJC_Final_Project\Loan_for_startup_business\disburstment\views.py", line 15, in get
    Installment_obj = get_object_or_404(Installment,loan=loan_id)
  File "D:\python files\CJC_Final_Project\venv\lib\site-packages\django\shortcuts.py", line 85, in get_object_or_404
    return queryset.get(*args, **kwargs)
  File "D:\python files\CJC_Final_Project\venv\lib\site-packages\django\db\models\query.py", line 640, in get
    raise self.model.MultipleObjectsReturned(
disburstment.models.Installment.MultipleObjectsReturned: get() returned more than one Installment -- it returned 3!
ERROR 2023-08-16 13:20:29,902 basehttp "GET /disburstment/installment/1/ HTTP/1.1" 500 111662
ERROR 2023-08-16 13:36:34,776 log Internal Server Error: /disburstment/installment/1/
Traceback (most recent call last):
  File "D:\python files\CJC_Final_Project\venv\lib\site-packages\django\core\handlers\exception.py", line 55, in inner
    response = get_response(request)
  File "D:\python files\CJC_Final_Project\venv\lib\site-packages\django\core\handlers\base.py", line 197, in _get_response
    response = wrapped_callback(request, *callback_args, **callback_kwargs)
  File "D:\python files\CJC_Final_Project\venv\lib\site-packages\django\views\decorators\csrf.py", line 56, in wrapper_view
    return view_func(*args, **kwargs)
  File "D:\python files\CJC_Final_Project\venv\lib\site-packages\django\views\generic\base.py", line 104, in view
    return self.dispatch(request, *args, **kwargs)
  File "D:\python files\CJC_Final_Project\venv\lib\site-packages\rest_framework\views.py", line 509, in dispatch
    response = self.handle_exception(exc)
  File "D:\python files\CJC_Final_Project\venv\lib\site-packages\rest_framework\views.py", line 469, in handle_exception
    self.raise_uncaught_exception(exc)
  File "D:\python files\CJC_Final_Project\venv\lib\site-packages\rest_framework\views.py", line 480, in raise_uncaught_exception
    raise exc
  File "D:\python files\CJC_Final_Project\venv\lib\site-packages\rest_framework\views.py", line 506, in dispatch
    response = handler(request, *args, **kwargs)
  File "D:\python files\CJC_Final_Project\Loan_for_startup_business\disburstment\views.py", line 15, in get
    Installment_obj = get_object_or_404(Installment,loan=loan_id)
  File "D:\python files\CJC_Final_Project\venv\lib\site-packages\django\shortcuts.py", line 85, in get_object_or_404
    return queryset.get(*args, **kwargs)
  File "D:\python files\CJC_Final_Project\venv\lib\site-packages\django\db\models\query.py", line 640, in get
    raise self.model.MultipleObjectsReturned(
disburstment.models.Installment.MultipleObjectsReturned: get() returned more than one Installment -- it returned 3!
ERROR 2023-08-16 13:36:34,781 basehttp "GET /disburstment/installment/1/ HTTP/1.1" 500 111662
ERROR 2023-08-16 13:37:21,562 log Internal Server Error: /disburstment/installment/1/
Traceback (most recent call last):
  File "D:\python files\CJC_Final_Project\venv\lib\site-packages\django\core\handlers\exception.py", line 55, in inner
    response = get_response(request)
  File "D:\python files\CJC_Final_Project\venv\lib\site-packages\django\core\handlers\base.py", line 197, in _get_response
    response = wrapped_callback(request, *callback_args, **callback_kwargs)
  File "D:\python files\CJC_Final_Project\venv\lib\site-packages\django\views\decorators\csrf.py", line 56, in wrapper_view
    return view_func(*args, **kwargs)
  File "D:\python files\CJC_Final_Project\venv\lib\site-packages\django\views\generic\base.py", line 104, in view
    return self.dispatch(request, *args, **kwargs)
  File "D:\python files\CJC_Final_Project\venv\lib\site-packages\rest_framework\views.py", line 509, in dispatch
    response = self.handle_exception(exc)
  File "D:\python files\CJC_Final_Project\venv\lib\site-packages\rest_framework\views.py", line 469, in handle_exception
    self.raise_uncaught_exception(exc)
  File "D:\python files\CJC_Final_Project\venv\lib\site-packages\rest_framework\views.py", line 480, in raise_uncaught_exception
    raise exc
  File "D:\python files\CJC_Final_Project\venv\lib\site-packages\rest_framework\views.py", line 506, in dispatch
    response = handler(request, *args, **kwargs)
  File "D:\python files\CJC_Final_Project\Loan_for_startup_business\disburstment\views.py", line 15, in get
    Installment_obj = get_object_or_404(Installment,loan=loan_id)
  File "D:\python files\CJC_Final_Project\venv\lib\site-packages\django\shortcuts.py", line 85, in get_object_or_404
    return queryset.get(*args, **kwargs)
  File "D:\python files\CJC_Final_Project\venv\lib\site-packages\django\db\models\query.py", line 640, in get
    raise self.model.MultipleObjectsReturned(
disburstment.models.Installment.MultipleObjectsReturned: get() returned more than one Installment -- it returned 3!
ERROR 2023-08-16 13:37:21,566 basehttp "GET /disburstment/installment/1/ HTTP/1.1" 500 111662
ERROR 2023-08-16 13:46:07,187 log Internal Server Error: /disburstment/installment/1/
Traceback (most recent call last):
  File "D:\python files\CJC_Final_Project\venv\lib\site-packages\django\core\handlers\exception.py", line 55, in inner
    response = get_response(request)
  File "D:\python files\CJC_Final_Project\venv\lib\site-packages\django\core\handlers\base.py", line 197, in _get_response
    response = wrapped_callback(request, *callback_args, **callback_kwargs)
  File "D:\python files\CJC_Final_Project\venv\lib\site-packages\django\views\decorators\csrf.py", line 56, in wrapper_view
    return view_func(*args, **kwargs)
  File "D:\python files\CJC_Final_Project\venv\lib\site-packages\django\views\generic\base.py", line 104, in view
    return self.dispatch(request, *args, **kwargs)
  File "D:\python files\CJC_Final_Project\venv\lib\site-packages\rest_framework\views.py", line 509, in dispatch
    response = self.handle_exception(exc)
  File "D:\python files\CJC_Final_Project\venv\lib\site-packages\rest_framework\views.py", line 469, in handle_exception
    self.raise_uncaught_exception(exc)
  File "D:\python files\CJC_Final_Project\venv\lib\site-packages\rest_framework\views.py", line 480, in raise_uncaught_exception
    raise exc
  File "D:\python files\CJC_Final_Project\venv\lib\site-packages\rest_framework\views.py", line 506, in dispatch
    response = handler(request, *args, **kwargs)
  File "D:\python files\CJC_Final_Project\Loan_for_startup_business\disburstment\views.py", line 15, in get
    Installment_obj = get_object_or_404(Installment,loan=loan_id)
  File "D:\python files\CJC_Final_Project\venv\lib\site-packages\django\shortcuts.py", line 85, in get_object_or_404
    return queryset.get(*args, **kwargs)
  File "D:\python files\CJC_Final_Project\venv\lib\site-packages\django\db\models\query.py", line 640, in get
    raise self.model.MultipleObjectsReturned(
disburstment.models.Installment.MultipleObjectsReturned: get() returned more than one Installment -- it returned 3!
ERROR 2023-08-16 13:46:07,192 basehttp "GET /disburstment/installment/1/ HTTP/1.1" 500 111652
ERROR 2023-08-16 15:07:09,912 log Internal Server Error: /disburstment/installment/7/
Traceback (most recent call last):
  File "D:\python files\CJC_Final_Project\venv\lib\site-packages\django\core\handlers\exception.py", line 55, in inner
    response = get_response(request)
  File "D:\python files\CJC_Final_Project\venv\lib\site-packages\django\core\handlers\base.py", line 197, in _get_response
    response = wrapped_callback(request, *callback_args, **callback_kwargs)
  File "D:\python files\CJC_Final_Project\venv\lib\site-packages\django\views\decorators\csrf.py", line 56, in wrapper_view
    return view_func(*args, **kwargs)
  File "D:\python files\CJC_Final_Project\venv\lib\site-packages\django\views\generic\base.py", line 104, in view
    return self.dispatch(request, *args, **kwargs)
  File "D:\python files\CJC_Final_Project\venv\lib\site-packages\rest_framework\views.py", line 509, in dispatch
    response = self.handle_exception(exc)
  File "D:\python files\CJC_Final_Project\venv\lib\site-packages\rest_framework\views.py", line 469, in handle_exception
    self.raise_uncaught_exception(exc)
  File "D:\python files\CJC_Final_Project\venv\lib\site-packages\rest_framework\views.py", line 480, in raise_uncaught_exception
    raise exc
  File "D:\python files\CJC_Final_Project\venv\lib\site-packages\rest_framework\views.py", line 506, in dispatch
    response = handler(request, *args, **kwargs)
  File "D:\python files\CJC_Final_Project\Loan_for_startup_business\disburstment\views.py", line 18, in get
    Installment_obj = get_object_or_404(Installment,loan=loan_id)
  File "D:\python files\CJC_Final_Project\venv\lib\site-packages\django\shortcuts.py", line 85, in get_object_or_404
    return queryset.get(*args, **kwargs)
  File "D:\python files\CJC_Final_Project\venv\lib\site-packages\django\db\models\query.py", line 640, in get
    raise self.model.MultipleObjectsReturned(
disburstment.models.Installment.MultipleObjectsReturned: get() returned more than one Installment -- it returned 3!
ERROR 2023-08-16 15:07:09,934 basehttp "GET /disburstment/installment/7/ HTTP/1.1" 500 111792
ERROR 2023-08-16 22:49:53,857 log Internal Server Error: /admin_app/loginpage/
Traceback (most recent call last):
  File "D:\python files\CJC_Final_Project\venv\lib\site-packages\django\core\handlers\exception.py", line 55, in inner
    response = get_response(request)
  File "D:\python files\CJC_Final_Project\venv\lib\site-packages\django\core\handlers\base.py", line 197, in _get_response
    response = wrapped_callback(request, *callback_args, **callback_kwargs)
  File "D:\python files\CJC_Final_Project\venv\lib\site-packages\django\views\decorators\csrf.py", line 56, in wrapper_view
    return view_func(*args, **kwargs)
  File "D:\python files\CJC_Final_Project\venv\lib\site-packages\django\views\generic\base.py", line 104, in view
    return self.dispatch(request, *args, **kwargs)
  File "D:\python files\CJC_Final_Project\venv\lib\site-packages\rest_framework\views.py", line 509, in dispatch
    response = self.handle_exception(exc)
  File "D:\python files\CJC_Final_Project\venv\lib\site-packages\rest_framework\views.py", line 469, in handle_exception
    self.raise_uncaught_exception(exc)
  File "D:\python files\CJC_Final_Project\venv\lib\site-packages\rest_framework\views.py", line 480, in raise_uncaught_exception
    raise exc
  File "D:\python files\CJC_Final_Project\venv\lib\site-packages\rest_framework\views.py", line 506, in dispatch
    response = handler(request, *args, **kwargs)
  File "D:\python files\CJC_Final_Project\Loan_for_startup_business\admin_app\views.py", line 35, in post
    print(user_obj.id)
AttributeError: 'QuerySet' object has no attribute 'id'
ERROR 2023-08-16 22:49:53,907 basehttp "POST /admin_app/loginpage/ HTTP/1.1" 500 104430
ERROR 2023-08-16 22:49:59,797 log Internal Server Error: /admin_app/loginpage/
Traceback (most recent call last):
  File "D:\python files\CJC_Final_Project\venv\lib\site-packages\django\core\handlers\exception.py", line 55, in inner
    response = get_response(request)
  File "D:\python files\CJC_Final_Project\venv\lib\site-packages\django\core\handlers\base.py", line 197, in _get_response
    response = wrapped_callback(request, *callback_args, **callback_kwargs)
  File "D:\python files\CJC_Final_Project\venv\lib\site-packages\django\views\decorators\csrf.py", line 56, in wrapper_view
    return view_func(*args, **kwargs)
  File "D:\python files\CJC_Final_Project\venv\lib\site-packages\django\views\generic\base.py", line 104, in view
    return self.dispatch(request, *args, **kwargs)
  File "D:\python files\CJC_Final_Project\venv\lib\site-packages\rest_framework\views.py", line 509, in dispatch
    response = self.handle_exception(exc)
  File "D:\python files\CJC_Final_Project\venv\lib\site-packages\rest_framework\views.py", line 469, in handle_exception
    self.raise_uncaught_exception(exc)
  File "D:\python files\CJC_Final_Project\venv\lib\site-packages\rest_framework\views.py", line 480, in raise_uncaught_exception
    raise exc
  File "D:\python files\CJC_Final_Project\venv\lib\site-packages\rest_framework\views.py", line 506, in dispatch
    response = handler(request, *args, **kwargs)
  File "D:\python files\CJC_Final_Project\Loan_for_startup_business\admin_app\views.py", line 35, in post
    print(user_obj.id)
AttributeError: 'QuerySet' object has no attribute 'id'
ERROR 2023-08-16 22:49:59,800 basehttp "POST /admin_app/loginpage/ HTTP/1.1" 500 104430
ERROR 2023-08-16 22:50:31,963 log Internal Server Error: /admin_app/loginpage/
Traceback (most recent call last):
  File "D:\python files\CJC_Final_Project\venv\lib\site-packages\django\core\handlers\exception.py", line 55, in inner
    response = get_response(request)
  File "D:\python files\CJC_Final_Project\venv\lib\site-packages\django\core\handlers\base.py", line 197, in _get_response
    response = wrapped_callback(request, *callback_args, **callback_kwargs)
  File "D:\python files\CJC_Final_Project\venv\lib\site-packages\django\views\decorators\csrf.py", line 56, in wrapper_view
    return view_func(*args, **kwargs)
  File "D:\python files\CJC_Final_Project\venv\lib\site-packages\django\views\generic\base.py", line 104, in view
    return self.dispatch(request, *args, **kwargs)
  File "D:\python files\CJC_Final_Project\venv\lib\site-packages\rest_framework\views.py", line 509, in dispatch
    response = self.handle_exception(exc)
  File "D:\python files\CJC_Final_Project\venv\lib\site-packages\rest_framework\views.py", line 469, in handle_exception
    self.raise_uncaught_exception(exc)
  File "D:\python files\CJC_Final_Project\venv\lib\site-packages\rest_framework\views.py", line 480, in raise_uncaught_exception
    raise exc
  File "D:\python files\CJC_Final_Project\venv\lib\site-packages\rest_framework\views.py", line 506, in dispatch
    response = handler(request, *args, **kwargs)
  File "D:\python files\CJC_Final_Project\Loan_for_startup_business\admin_app\views.py", line 35, in post
    print(user_obj['id'])
  File "D:\python files\CJC_Final_Project\venv\lib\site-packages\django\db\models\query.py", line 418, in __getitem__
    raise TypeError(
TypeError: QuerySet indices must be integers or slices, not str.
ERROR 2023-08-16 22:50:31,968 basehttp "POST /admin_app/loginpage/ HTTP/1.1" 500 108145
ERROR 2023-08-16 22:50:57,769 log Internal Server Error: /admin_app/loginpage/
Traceback (most recent call last):
  File "D:\python files\CJC_Final_Project\venv\lib\site-packages\django\core\handlers\exception.py", line 55, in inner
    response = get_response(request)
  File "D:\python files\CJC_Final_Project\venv\lib\site-packages\django\core\handlers\base.py", line 197, in _get_response
    response = wrapped_callback(request, *callback_args, **callback_kwargs)
  File "D:\python files\CJC_Final_Project\venv\lib\site-packages\django\views\decorators\csrf.py", line 56, in wrapper_view
    return view_func(*args, **kwargs)
  File "D:\python files\CJC_Final_Project\venv\lib\site-packages\django\views\generic\base.py", line 104, in view
    return self.dispatch(request, *args, **kwargs)
  File "D:\python files\CJC_Final_Project\venv\lib\site-packages\rest_framework\views.py", line 509, in dispatch
    response = self.handle_exception(exc)
  File "D:\python files\CJC_Final_Project\venv\lib\site-packages\rest_framework\views.py", line 469, in handle_exception
    self.raise_uncaught_exception(exc)
  File "D:\python files\CJC_Final_Project\venv\lib\site-packages\rest_framework\views.py", line 480, in raise_uncaught_exception
    raise exc
  File "D:\python files\CJC_Final_Project\venv\lib\site-packages\rest_framework\views.py", line 506, in dispatch
    response = handler(request, *args, **kwargs)
  File "D:\python files\CJC_Final_Project\Loan_for_startup_business\admin_app\views.py", line 35, in post
    print(user_obj.get('id'))
  File "D:\python files\CJC_Final_Project\venv\lib\site-packages\django\db\models\query.py", line 623, in get
    clone = self._chain() if self.query.combinator else self.filter(*args, **kwargs)
  File "D:\python files\CJC_Final_Project\venv\lib\site-packages\django\db\models\query.py", line 1436, in filter
    return self._filter_or_exclude(False, args, kwargs)
  File "D:\python files\CJC_Final_Project\venv\lib\site-packages\django\db\models\query.py", line 1454, in _filter_or_exclude
    clone._filter_or_exclude_inplace(negate, args, kwargs)
  File "D:\python files\CJC_Final_Project\venv\lib\site-packages\django\db\models\query.py", line 1461, in _filter_or_exclude_inplace
    self._query.add_q(Q(*args, **kwargs))
  File "D:\python files\CJC_Final_Project\venv\lib\site-packages\django\db\models\sql\query.py", line 1545, in add_q
    clause, _ = self._add_q(q_object, self.used_aliases)
  File "D:\python files\CJC_Final_Project\venv\lib\site-packages\django\db\models\sql\query.py", line 1576, in _add_q
    child_clause, needed_inner = self.build_filter(
  File "D:\python files\CJC_Final_Project\venv\lib\site-packages\django\db\models\sql\query.py", line 1426, in build_filter
    lookups, parts, reffed_expression = self.solve_lookup_type(arg, summarize)
  File "D:\python files\CJC_Final_Project\venv\lib\site-packages\django\db\models\sql\query.py", line 1236, in solve_lookup_type
    _, field, _, lookup_parts = self.names_to_path(lookup_splitted, self.get_meta())
  File "D:\python files\CJC_Final_Project\venv\lib\site-packages\django\db\models\sql\query.py", line 1724, in names_to_path
    raise FieldError(
django.core.exceptions.FieldError: Cannot resolve keyword 'i' into field. Choices are: Applications, banks, current_address, date_joined, defaulters, dob, email, family, first_name, gender, groups, id, is_active, is_staff, is_superuser, last_login, last_name, logentry, mobile, password, permanent_address, photo, role, signature, user_permissions, username
ERROR 2023-08-16 22:50:57,774 basehttp "POST /admin_app/loginpage/ HTTP/1.1" 500 149059
ERROR 2023-08-16 22:53:21,442 log Internal Server Error: /admin_app/loginpage/
Traceback (most recent call last):
  File "D:\python files\CJC_Final_Project\venv\lib\site-packages\django\core\handlers\exception.py", line 55, in inner
    response = get_response(request)
  File "D:\python files\CJC_Final_Project\venv\lib\site-packages\django\core\handlers\base.py", line 197, in _get_response
    response = wrapped_callback(request, *callback_args, **callback_kwargs)
  File "D:\python files\CJC_Final_Project\venv\lib\site-packages\django\views\decorators\csrf.py", line 56, in wrapper_view
    return view_func(*args, **kwargs)
  File "D:\python files\CJC_Final_Project\venv\lib\site-packages\django\views\generic\base.py", line 104, in view
    return self.dispatch(request, *args, **kwargs)
  File "D:\python files\CJC_Final_Project\venv\lib\site-packages\rest_framework\views.py", line 509, in dispatch
    response = self.handle_exception(exc)
  File "D:\python files\CJC_Final_Project\venv\lib\site-packages\rest_framework\views.py", line 469, in handle_exception
    self.raise_uncaught_exception(exc)
  File "D:\python files\CJC_Final_Project\venv\lib\site-packages\rest_framework\views.py", line 480, in raise_uncaught_exception
    raise exc
  File "D:\python files\CJC_Final_Project\venv\lib\site-packages\rest_framework\views.py", line 506, in dispatch
    response = handler(request, *args, **kwargs)
  File "D:\python files\CJC_Final_Project\Loan_for_startup_business\admin_app\views.py", line 35, in post
    print(user_obj.id)
AttributeError: 'QuerySet' object has no attribute 'id'
ERROR 2023-08-16 22:53:21,445 basehttp "POST /admin_app/loginpage/ HTTP/1.1" 500 104436
ERROR 2023-08-16 23:24:24,524 log Internal Server Error: /customer/loandata/a@gmail.com/
Traceback (most recent call last):
  File "D:\python files\CJC_Final_Project\venv\lib\site-packages\django\core\handlers\exception.py", line 55, in inner
    response = get_response(request)
  File "D:\python files\CJC_Final_Project\venv\lib\site-packages\django\core\handlers\base.py", line 197, in _get_response
    response = wrapped_callback(request, *callback_args, **callback_kwargs)
  File "D:\python files\CJC_Final_Project\venv\lib\site-packages\django\views\decorators\csrf.py", line 56, in wrapper_view
    return view_func(*args, **kwargs)
  File "D:\python files\CJC_Final_Project\venv\lib\site-packages\django\views\generic\base.py", line 104, in view
    return self.dispatch(request, *args, **kwargs)
  File "D:\python files\CJC_Final_Project\venv\lib\site-packages\rest_framework\views.py", line 509, in dispatch
    response = self.handle_exception(exc)
  File "D:\python files\CJC_Final_Project\venv\lib\site-packages\rest_framework\views.py", line 469, in handle_exception
    self.raise_uncaught_exception(exc)
  File "D:\python files\CJC_Final_Project\venv\lib\site-packages\rest_framework\views.py", line 480, in raise_uncaught_exception
    raise exc
  File "D:\python files\CJC_Final_Project\venv\lib\site-packages\rest_framework\views.py", line 506, in dispatch
    response = handler(request, *args, **kwargs)
  File "D:\python files\CJC_Final_Project\Loan_for_startup_business\customer\views.py", line 79, in get
    user_obj = User.objects.select_related(email=email)
  File "D:\python files\CJC_Final_Project\venv\lib\site-packages\django\db\models\manager.py", line 87, in manager_method
    return getattr(self.get_queryset(), name)(*args, **kwargs)
TypeError: QuerySet.select_related() got an unexpected keyword argument 'email'
ERROR 2023-08-16 23:24:24,527 basehttp "GET /customer/loandata/a@gmail.com/ HTTP/1.1" 500 106720
ERROR 2023-08-16 23:32:24,515 log Internal Server Error: /customer/loandata/a@gmail.com/
Traceback (most recent call last):
  File "D:\python files\CJC_Final_Project\venv\lib\site-packages\django\core\handlers\exception.py", line 55, in inner
    response = get_response(request)
  File "D:\python files\CJC_Final_Project\venv\lib\site-packages\django\core\handlers\base.py", line 197, in _get_response
    response = wrapped_callback(request, *callback_args, **callback_kwargs)
  File "D:\python files\CJC_Final_Project\venv\lib\site-packages\django\views\decorators\csrf.py", line 56, in wrapper_view
    return view_func(*args, **kwargs)
  File "D:\python files\CJC_Final_Project\venv\lib\site-packages\django\views\generic\base.py", line 104, in view
    return self.dispatch(request, *args, **kwargs)
  File "D:\python files\CJC_Final_Project\venv\lib\site-packages\rest_framework\views.py", line 509, in dispatch
    response = self.handle_exception(exc)
  File "D:\python files\CJC_Final_Project\venv\lib\site-packages\rest_framework\views.py", line 469, in handle_exception
    self.raise_uncaught_exception(exc)
  File "D:\python files\CJC_Final_Project\venv\lib\site-packages\rest_framework\views.py", line 480, in raise_uncaught_exception
    raise exc
  File "D:\python files\CJC_Final_Project\venv\lib\site-packages\rest_framework\views.py", line 506, in dispatch
    response = handler(request, *args, **kwargs)
  File "D:\python files\CJC_Final_Project\Loan_for_startup_business\customer\views.py", line 85, in get
    Loan_obj = Loan.objects.select_related('application').get(application=id)
  File "D:\python files\CJC_Final_Project\venv\lib\site-packages\django\db\models\query.py", line 637, in get
    raise self.model.DoesNotExist(
loan_sanctioning.models.Loan.DoesNotExist: Loan matching query does not exist.
ERROR 2023-08-16 23:32:24,518 basehttp "GET /customer/loandata/a@gmail.com/ HTTP/1.1" 500 108717
ERROR 2023-08-16 23:33:45,124 log Internal Server Error: /customer/loandata/a@gmail.com/
Traceback (most recent call last):
  File "D:\python files\CJC_Final_Project\venv\lib\site-packages\django\core\handlers\exception.py", line 55, in inner
    response = get_response(request)
  File "D:\python files\CJC_Final_Project\venv\lib\site-packages\django\core\handlers\base.py", line 197, in _get_response
    response = wrapped_callback(request, *callback_args, **callback_kwargs)
  File "D:\python files\CJC_Final_Project\venv\lib\site-packages\django\views\decorators\csrf.py", line 56, in wrapper_view
    return view_func(*args, **kwargs)
  File "D:\python files\CJC_Final_Project\venv\lib\site-packages\django\views\generic\base.py", line 104, in view
    return self.dispatch(request, *args, **kwargs)
  File "D:\python files\CJC_Final_Project\venv\lib\site-packages\rest_framework\views.py", line 509, in dispatch
    response = self.handle_exception(exc)
  File "D:\python files\CJC_Final_Project\venv\lib\site-packages\rest_framework\views.py", line 469, in handle_exception
    self.raise_uncaught_exception(exc)
  File "D:\python files\CJC_Final_Project\venv\lib\site-packages\rest_framework\views.py", line 480, in raise_uncaught_exception
    raise exc
  File "D:\python files\CJC_Final_Project\venv\lib\site-packages\rest_framework\views.py", line 506, in dispatch
    response = handler(request, *args, **kwargs)
  File "D:\python files\CJC_Final_Project\Loan_for_startup_business\customer\views.py", line 85, in get
    Loan_obj = Loan.objects.select_related('application').get(application=id)
  File "D:\python files\CJC_Final_Project\venv\lib\site-packages\django\db\models\query.py", line 637, in get
    raise self.model.DoesNotExist(
loan_sanctioning.models.Loan.DoesNotExist: Loan matching query does not exist.
ERROR 2023-08-16 23:33:45,128 basehttp "GET /customer/loandata/a@gmail.com/ HTTP/1.1" 500 108717
ERROR 2023-08-16 23:34:49,630 log Internal Server Error: /customer/loandata/u@gmail.com/
Traceback (most recent call last):
  File "D:\python files\CJC_Final_Project\venv\lib\site-packages\django\core\handlers\exception.py", line 55, in inner
    response = get_response(request)
  File "D:\python files\CJC_Final_Project\venv\lib\site-packages\django\core\handlers\base.py", line 197, in _get_response
    response = wrapped_callback(request, *callback_args, **callback_kwargs)
  File "D:\python files\CJC_Final_Project\venv\lib\site-packages\django\views\decorators\csrf.py", line 56, in wrapper_view
    return view_func(*args, **kwargs)
  File "D:\python files\CJC_Final_Project\venv\lib\site-packages\django\views\generic\base.py", line 104, in view
    return self.dispatch(request, *args, **kwargs)
  File "D:\python files\CJC_Final_Project\venv\lib\site-packages\rest_framework\views.py", line 509, in dispatch
    response = self.handle_exception(exc)
  File "D:\python files\CJC_Final_Project\venv\lib\site-packages\rest_framework\views.py", line 469, in handle_exception
    self.raise_uncaught_exception(exc)
  File "D:\python files\CJC_Final_Project\venv\lib\site-packages\rest_framework\views.py", line 480, in raise_uncaught_exception
    raise exc
  File "D:\python files\CJC_Final_Project\venv\lib\site-packages\rest_framework\views.py", line 506, in dispatch
    response = handler(request, *args, **kwargs)
  File "D:\python files\CJC_Final_Project\Loan_for_startup_business\customer\views.py", line 85, in get
    Loan_obj = Loan.objects.select_related('application').get(application=id)
  File "D:\python files\CJC_Final_Project\venv\lib\site-packages\django\db\models\query.py", line 637, in get
    raise self.model.DoesNotExist(
loan_sanctioning.models.Loan.DoesNotExist: Loan matching query does not exist.
ERROR 2023-08-16 23:34:49,669 basehttp "GET /customer/loandata/u@gmail.com/ HTTP/1.1" 500 108717
ERROR 2023-08-16 23:38:26,368 log Internal Server Error: /customer/loandata/u@gmail.com/
Traceback (most recent call last):
  File "D:\python files\CJC_Final_Project\venv\lib\site-packages\django\core\handlers\exception.py", line 55, in inner
    response = get_response(request)
  File "D:\python files\CJC_Final_Project\venv\lib\site-packages\django\core\handlers\base.py", line 197, in _get_response
    response = wrapped_callback(request, *callback_args, **callback_kwargs)
  File "D:\python files\CJC_Final_Project\venv\lib\site-packages\django\views\decorators\csrf.py", line 56, in wrapper_view
    return view_func(*args, **kwargs)
  File "D:\python files\CJC_Final_Project\venv\lib\site-packages\django\views\generic\base.py", line 104, in view
    return self.dispatch(request, *args, **kwargs)
  File "D:\python files\CJC_Final_Project\venv\lib\site-packages\rest_framework\views.py", line 509, in dispatch
    response = self.handle_exception(exc)
  File "D:\python files\CJC_Final_Project\venv\lib\site-packages\rest_framework\views.py", line 469, in handle_exception
    self.raise_uncaught_exception(exc)
  File "D:\python files\CJC_Final_Project\venv\lib\site-packages\rest_framework\views.py", line 480, in raise_uncaught_exception
    raise exc
  File "D:\python files\CJC_Final_Project\venv\lib\site-packages\rest_framework\views.py", line 506, in dispatch
    response = handler(request, *args, **kwargs)
  File "D:\python files\CJC_Final_Project\Loan_for_startup_business\customer\views.py", line 86, in get
    Loan_obj = Application.objects.select_related('user').get(application=id)
  File "D:\python files\CJC_Final_Project\venv\lib\site-packages\django\db\models\query.py", line 623, in get
    clone = self._chain() if self.query.combinator else self.filter(*args, **kwargs)
  File "D:\python files\CJC_Final_Project\venv\lib\site-packages\django\db\models\query.py", line 1436, in filter
    return self._filter_or_exclude(False, args, kwargs)
  File "D:\python files\CJC_Final_Project\venv\lib\site-packages\django\db\models\query.py", line 1454, in _filter_or_exclude
    clone._filter_or_exclude_inplace(negate, args, kwargs)
  File "D:\python files\CJC_Final_Project\venv\lib\site-packages\django\db\models\query.py", line 1461, in _filter_or_exclude_inplace
    self._query.add_q(Q(*args, **kwargs))
  File "D:\python files\CJC_Final_Project\venv\lib\site-packages\django\db\models\sql\query.py", line 1545, in add_q
    clause, _ = self._add_q(q_object, self.used_aliases)
  File "D:\python files\CJC_Final_Project\venv\lib\site-packages\django\db\models\sql\query.py", line 1576, in _add_q
    child_clause, needed_inner = self.build_filter(
  File "D:\python files\CJC_Final_Project\venv\lib\site-packages\django\db\models\sql\query.py", line 1426, in build_filter
    lookups, parts, reffed_expression = self.solve_lookup_type(arg, summarize)
  File "D:\python files\CJC_Final_Project\venv\lib\site-packages\django\db\models\sql\query.py", line 1236, in solve_lookup_type
    _, field, _, lookup_parts = self.names_to_path(lookup_splitted, self.get_meta())
  File "D:\python files\CJC_Final_Project\venv\lib\site-packages\django\db\models\sql\query.py", line 1724, in names_to_path
    raise FieldError(
django.core.exceptions.FieldError: Cannot resolve keyword 'application' into field. Choices are: Gaurantors, Loans, Vendors, aaddar_no, application_timestamp, business_address, business_license_no, business_title, business_type, collateral, documents, expected_average_annual_turnover, gst_registration_no, id, pan_no, remark, status, type_of_employment, user, user_id, years_in_current_business
ERROR 2023-08-16 23:38:26,375 basehttp "GET /customer/loandata/u@gmail.com/ HTTP/1.1" 500 150361
ERROR 2023-08-16 23:40:53,509 log Internal Server Error: /customer/loandata/u@gmail.com/
Traceback (most recent call last):
  File "D:\python files\CJC_Final_Project\venv\lib\site-packages\django\db\models\fields\__init__.py", line 2053, in get_prep_value
    return int(value)
ValueError: invalid literal for int() with base 10: 'u@gmail.com'

The above exception was the direct cause of the following exception:

Traceback (most recent call last):
  File "D:\python files\CJC_Final_Project\venv\lib\site-packages\django\core\handlers\exception.py", line 55, in inner
    response = get_response(request)
  File "D:\python files\CJC_Final_Project\venv\lib\site-packages\django\core\handlers\base.py", line 197, in _get_response
    response = wrapped_callback(request, *callback_args, **callback_kwargs)
  File "D:\python files\CJC_Final_Project\venv\lib\site-packages\django\views\decorators\csrf.py", line 56, in wrapper_view
    return view_func(*args, **kwargs)
  File "D:\python files\CJC_Final_Project\venv\lib\site-packages\django\views\generic\base.py", line 104, in view
    return self.dispatch(request, *args, **kwargs)
  File "D:\python files\CJC_Final_Project\venv\lib\site-packages\rest_framework\views.py", line 509, in dispatch
    response = self.handle_exception(exc)
  File "D:\python files\CJC_Final_Project\venv\lib\site-packages\rest_framework\views.py", line 469, in handle_exception
    self.raise_uncaught_exception(exc)
  File "D:\python files\CJC_Final_Project\venv\lib\site-packages\rest_framework\views.py", line 480, in raise_uncaught_exception
    raise exc
  File "D:\python files\CJC_Final_Project\venv\lib\site-packages\rest_framework\views.py", line 506, in dispatch
    response = handler(request, *args, **kwargs)
  File "D:\python files\CJC_Final_Project\Loan_for_startup_business\customer\views.py", line 86, in get
    Loan_obj = Application.objects.select_related('user').get(user=email)
  File "D:\python files\CJC_Final_Project\venv\lib\site-packages\django\db\models\query.py", line 623, in get
    clone = self._chain() if self.query.combinator else self.filter(*args, **kwargs)
  File "D:\python files\CJC_Final_Project\venv\lib\site-packages\django\db\models\query.py", line 1436, in filter
    return self._filter_or_exclude(False, args, kwargs)
  File "D:\python files\CJC_Final_Project\venv\lib\site-packages\django\db\models\query.py", line 1454, in _filter_or_exclude
    clone._filter_or_exclude_inplace(negate, args, kwargs)
  File "D:\python files\CJC_Final_Project\venv\lib\site-packages\django\db\models\query.py", line 1461, in _filter_or_exclude_inplace
    self._query.add_q(Q(*args, **kwargs))
  File "D:\python files\CJC_Final_Project\venv\lib\site-packages\django\db\models\sql\query.py", line 1545, in add_q
    clause, _ = self._add_q(q_object, self.used_aliases)
  File "D:\python files\CJC_Final_Project\venv\lib\site-packages\django\db\models\sql\query.py", line 1576, in _add_q
    child_clause, needed_inner = self.build_filter(
  File "D:\python files\CJC_Final_Project\venv\lib\site-packages\django\db\models\sql\query.py", line 1491, in build_filter
    condition = self.build_lookup(lookups, col, value)
  File "D:\python files\CJC_Final_Project\venv\lib\site-packages\django\db\models\sql\query.py", line 1318, in build_lookup
    lookup = lookup_class(lhs, rhs)
  File "D:\python files\CJC_Final_Project\venv\lib\site-packages\django\db\models\lookups.py", line 27, in __init__
    self.rhs = self.get_prep_lookup()
  File "D:\python files\CJC_Final_Project\venv\lib\site-packages\django\db\models\fields\related_lookups.py", line 166, in get_prep_lookup
    self.rhs = target_field.get_prep_value(self.rhs)
  File "D:\python files\CJC_Final_Project\venv\lib\site-packages\django\db\models\fields\__init__.py", line 2055, in get_prep_value
    raise e.__class__(
ValueError: Field 'id' expected a number but got 'u@gmail.com'.
ERROR 2023-08-16 23:40:53,516 basehttp "GET /customer/loandata/u@gmail.com/ HTTP/1.1" 500 162805
